Workbook

Sheet Manual
B2: 1) Go to the sheet named after the current month!
B6: 2) Create a list of habits you want to track
B25: 3) Mark your habit completion every day! The results of some habits aren't immediately visible – the key is to keep going. The chart will help you track your progress!
B45: 4) Don't forget about your emotional state!
B64: 5) Go to the "Dashboard" sheet.
B69: 6) Analyze your monthly habit progress! The chart shows which month you were most effective in!
B94: Done! You now have your own copy of the tracker to work with and customize. Use the tracker every day and watch how small steps lead to big results! If you have any questions, email us at: focus_lab@mail.ru

Sheet Dashboard
B2: Yearly Statistics
B6: Месяца | C6: Прогресс
B7: Nov | C7: =C24 -> 0
B8: Dec | C8: =F24 -> 0
B9: Jan | C9: =I24 -> 0
B10: Feb | C10: =L24 -> 0
B11: Mar | C11: =C29 -> 0
B12: Apr | C12: =F29 -> 0
B13: May | C13: =I29 -> 0
B14: Jun | C14: =L29 -> 0
B15: Jul | C15: =C34 -> 0
B16: Aug | C16: =F34 -> 0
B17: Sep | C17: =I34 -> 0
B18: Oct | C18: =L34 -> 0
B21: November | E21: December | H21: January | K21: Febrary
B22: Number of Habits | C22: =Nov!J4 -> 0 | E22: Number of Habits | F22: =Dec!J4 -> 0 | H22: Number of Habits | I22: =Jan!J4 -> 0 | K22: Number of Habits | L22: =Feb!J4 -> 0
B23: Completed | C23: =Nov!P4 -> 0 | E23: Completed | F23: =Dec!P4 -> 0 | H23: Completed | I23: =Jan!P4 -> 0 | K23: Completed | L23: =Feb!P4 -> 0
B24: Progress | C24: =Nov!AB4 -> 0 | E24: Progress | F24: =Dec!AB4 -> 0 | H24: Progress | I24: =Jan!AB4 -> 0 | K24: Progress | L24: =Feb!AB4 -> 0
B26: March | E26: April | H26: May | K26: June
B27: Number of Habits | C27: =Mar!J4 -> 0 | E27: Number of Habits | F27: =Apr!J4 -> 0 | H27: Number of Habits | I27: =May!J4 -> 0 | K27: Number of Habits | L27: =Jun!J4 -> 0
B28: Completed | C28: =Mar!P4 -> 0 | E28: Completed | F28: =Apr!P4 -> 0 | H28: Completed | I28: =May!P4 -> 0 | K28: Completed | L28: =Jun!P4 -> 0
B29: Progress | C29: =Mar!AB4 -> 0 | E29: Progress | F29: =Apr!AB4 -> 0 | H29: Progress | I29: =May!AB4 -> 0 | K29: Progress | L29: =Jun!AB4 -> 0
B31: Jule | E31: August | H31: Seprember | K31: October
B32: Number of Habits | C32: =Jul!J4 -> 0 | E32: Number of Habits | F32: =Aug!J4 -> 0 | H32: Number of Habits | I32: =Sep!J4 -> 0 | K32: Number of Habits | L32: =Oct!J4 -> 0
B33: Completed | C33: =Jul!P4 -> 0 | E33: Completed | F33: =Aug!P4 -> 0 | H33: Completed | I33: =Sep!P4 -> 0 | K33: Completed | L33: =Oct!P4 -> 0
B34: Progress | C34: =Jul!AB4 -> 0 | E34: Progress | F34: =Aug!AB4 -> 0 | H34: Progress | I34: =Sep!AB4 -> 0 | K34: Progress | L34: =Oct!AB4 -> 0

Sheet Example
B3: November | J3: Number of habits | P3: Completed habits | V3: Progress | AB3: Progress in %
J4: =COUNTA($B$10:$B$19) -> 10 | P4: =COUNTIF($C$10:$AF$19, TRUE) -> 163 | V4: =IFERROR(__xludf.DUMMYFUNCTION("SPARKLINE(AB4, {""charttype"",""bar"";""max"",1;""color1"",""#90EE90""})"),"") | AB4: =(P4)/(COUNTA($C$10:$C$19)*COUNTA($C$10:$AF$10)) -> 0.54333333
B7: My Habits | C7: Week 1 | J7: Week 2 | Q7: Week 3 | X7: Week 4 | AH7: Analysis
C8: Sa | D8: Su | E8: Mo | F8: Tu | G8: We | H8: Th | I8: Fr | J8: Sa | K8: Su | L8: Mo | M8: Tu | N8: We | O8: Th | P8: Fr | Q8: Sa | R8: Su | S8: Mo | T8: Tu | U8: We | V8: Th | W8: Fr | X8: Sa | Y8: Su | Z8: Mo | AA8: Tu | AB8: We | AC8: Th | AD8: Fr | AE8: Sa | AF8: Su
C9: 1 | D9: 2 | E9: 3 | F9: 4 | G9: 5 | H9: 6 | I9: 7 | J9: 8 | K9: 9 | L9: 10 | M9: 11 | N9: 12 | O9: 13 | P9: 14 | Q9: 15 | R9: 16 | S9: 17 | T9: 18 | U9: 19 | V9: 20 | W9: 21 | X9: 22 | Y9: 23 | Z9: 24 | AA9: 25 | AB9: 26 | AC9: 27 | AD9: 28 | AE9: 29 | AF9: 30 | AH9: Goal | AI9: Actual | AJ9: Progress
B10: Wake up at 05:00 ⏰ | C10: TRUE | D10: TRUE | E10: TRUE | F10: FALSE | G10: FALSE | H10: FALSE | I10: TRUE | J10: TRUE | K10: TRUE | L10: TRUE | M10: TRUE | N10: FALSE | O10: TRUE | P10: TRUE | Q10: TRUE | R10: FALSE | S10: TRUE | T10: TRUE | U10: TRUE | V10: FALSE | W10: FALSE | X10: FALSE | Y10: TRUE | Z10: FALSE | AA10: FALSE | AB10: TRUE | AC10: FALSE | AD10: FALSE | AE10: FALSE | AF10: TRUE | AH10: =30 -> 30 | AI10: =COUNTIF(C10:AF10, TRUE) -> 17 | AJ10: =IFERROR(__xludf.DUMMYFUNCTION("SPARKLINE(AI10/AH10, {""charttype"",""bar"";""max"",1;""color1"",""#90EE90""})"),"")
B11: Gym 💪 | C11: TRUE | D11: TRUE | E11: TRUE | F11: FALSE | G11: FALSE | H11: FALSE | I11: TRUE | J11: TRUE | K11: FALSE | L11: TRUE | M11: TRUE | N11: FALSE | O11: TRUE | P11: TRUE | Q11: TRUE | R11: TRUE | S11: TRUE | T11: TRUE | U11: TRUE | V11: FALSE | W11: FALSE | X11: TRUE | Y11: TRUE | Z11: FALSE | AA11: TRUE | AB11: TRUE | AC11: TRUE | AD11: FALSE | AE11: FALSE | AF11: FALSE | AH11: =30 -> 30 | AI11: =COUNTIF(C11:AF11, TRUE) -> 19 | AJ11: =IFERROR(__xludf.DUMMYFUNCTION("SPARKLINE(AI11/AH11, {""charttype"",""bar"";""max"",1;""color1"",""#90EE90""})"),"")
B12: Reading / Learning 📖 | C12: TRUE | D12: TRUE | E12: TRUE | F12: FALSE | G12: TRUE | H12: TRUE | I12: TRUE | J12: TRUE | K12: FALSE | L12: FALSE | M12: FALSE | N12: FALSE | O12: TRUE | P12: TRUE | Q12: TRUE | R12: TRUE | S12: FALSE | T12: TRUE | U12: TRUE | V12: FALSE | W12: FALSE | X12: TRUE | Y12: TRUE | Z12: FALSE | AA12: TRUE | AB12: FALSE | AC12: TRUE | AD12: FALSE | AE12: TRUE | AF12: TRUE | AH12: =30 -> 30 | AI12: =COUNTIF(C12:AF12, TRUE) -> 19 | AJ12: =IFERROR(__xludf.DUMMYFUNCTION("SPARKLINE(AI12/AH12, {""charttype"",""bar"";""max"",1;""color1"",""#90EE90""})"),"")
B13: Day Planning 🗓️ | C13: TRUE | D13: TRUE | E13: TRUE | F13: FALSE | G13: TRUE | H13: TRUE | I13: FALSE | J13: FALSE | K13: TRUE | L13: FALSE | M13: TRUE | N13: TRUE | O13: TRUE | P13: TRUE | Q13: TRUE | R13: TRUE | S13: TRUE | T13: TRUE | U13: TRUE | V13: TRUE | W13: FALSE | X13: TRUE | Y13: TRUE | Z13: TRUE | AA13: FALSE | AB13: FALSE | AC13: TRUE | AD13: TRUE | AE13: TRUE | AF13: TRUE | AH13: =30 -> 30 | AI13: =COUNTIF(C13:AF13, TRUE) -> 23 | AJ13: =IFERROR(__xludf.DUMMYFUNCTION("SPARKLINE(AI13/AH13, {""charttype"",""bar"";""max"",1;""color1"",""#90EE90""})"),"")
B14: Budget Tracking 💰 | C14: TRUE | D14: TRUE | E14: TRUE | F14: FALSE | G14: TRUE | H14: TRUE | I14: TRUE | J14: FALSE | K14: TRUE | L14: FALSE | M14: TRUE | N14: TRUE | O14: TRUE | P14: FALSE | Q14: TRUE | R14: TRUE | S14: TRUE | T14: TRUE | U14: TRUE | V14: TRUE | W14: TRUE | X14: TRUE | Y14: TRUE | Z14: TRUE | AA14: FALSE | AB14: TRUE | AC14: TRUE | AD14: TRUE | AE14: FALSE | AF14: TRUE | AH14: =30 -> 30 | AI14: =COUNTIF(C14:AF14, TRUE) -> 24 | AJ14: =IFERROR(__xludf.DUMMYFUNCTION("SPARKLINE(AI14/AH14, {""charttype"",""bar"";""max"",1;""color1"",""#90EE90""})"),"")
B15: Project Work 🎯 | C15: TRUE | D15: TRUE | E15: FALSE | F15: TRUE | G15: TRUE | H15: TRUE | I15: FALSE | J15: TRUE | K15: TRUE | L15: FALSE | M15: TRUE | N15: TRUE | O15: TRUE | P15: TRUE | Q15: TRUE | R15: TRUE | S15: TRUE | T15: TRUE | U15: FALSE | V15: TRUE | W15: TRUE | X15: TRUE | Y15: TRUE | Z15: TRUE | AA15: FALSE | AB15: TRUE | AC15: FALSE | AD15: TRUE | AE15: TRUE | AF15: TRUE | AH15: =30 -> 30 | AI15: =COUNTIF(C15:AF15, TRUE) -> 24 | AJ15: =IFERROR(__xludf.DUMMYFUNCTION("SPARKLINE(AI15/AH15, {""charttype"",""bar"";""max"",1;""color1"",""#90EE90""})"),"")
B16: No Alcohol 🍾 | C16: TRUE | D16: FALSE | E16: TRUE | F16: TRUE | G16: FALSE | H16: FALSE | I16: TRUE | J16: FALSE | K16: FALSE | L16: FALSE | M16: TRUE | N16: FALSE | O16: FALSE | P16: FALSE | Q16: TRUE | R16: TRUE | S16: TRUE | T16: FALSE | U16: FALSE | V16: FALSE | W16: TRUE | X16: FALSE | Y16: FALSE | Z16: FALSE | AA16: TRUE | AB16: TRUE | AC16: TRUE | AD16: TRUE | AE16: TRUE | AF16: TRUE | AH16: =30 -> 30 | AI16: =COUNTIF(C16:AF16, TRUE) -> 15 | AJ16: =IFERROR(__xludf.DUMMYFUNCTION("SPARKLINE(AI16/AH16, {""charttype"",""bar"";""max"",1;""color1"",""#90EE90""})"),"")
B17: Social Media Detox 🌿 | C17: FALSE | D17: FALSE | E17: TRUE | F17: TRUE | G17: FALSE | H17: FALSE | I17: TRUE | J17: TRUE | K17: TRUE | L17: FALSE | M17: TRUE | N17: FALSE | O17: FALSE | P17: FALSE | Q17: TRUE | R17: TRUE | S17: FALSE | T17: FALSE | U17: FALSE | V17: FALSE | W17: FALSE | X17: FALSE | Y17: FALSE | Z17: FALSE | AA17: FALSE | AB17: FALSE | AC17: FALSE | AD17: FALSE | AE17: FALSE | AF17: FALSE | AH17: =30 -> 30 | AI17: =COUNTIF(C17:AF17, TRUE) -> 8 | AJ17: =IFERROR(__xludf.DUMMYFUNCTION("SPARKLINE(AI17/AH17, {""charttype"",""bar"";""max"",1;""color1"",""#90EE90""})"),"")
B18: Goal Journaling 📔 | C18: TRUE | D18: TRUE | E18: FALSE | F18: TRUE | G18: FALSE | H18: FALSE | I18: FALSE | J18: FALSE | K18: TRUE | L18: FALSE | M18: TRUE | N18: FALSE | O18: FALSE | P18: FALSE | Q18: TRUE | R18: TRUE | S18: FALSE | T18: FALSE | U18: FALSE | V18: FALSE | W18: FALSE | X18: FALSE | Y18: FALSE | Z18: FALSE | AA18: FALSE | AB18: FALSE | AC18: FALSE | AD18: FALSE | AE18: FALSE | AF18: FALSE | AH18: =30 -> 30 | AI18: =COUNTIF(C18:AF18, TRUE) -> 7 | AJ18: =IFERROR(__xludf.DUMMYFUNCTION("SPARKLINE(AI18/AH18, {""charttype"",""bar"";""max"",1;""color1"",""#90EE90""})"),"")
B19: Cold Shower 🚿 | C19: TRUE | D19: FALSE | E19: TRUE | F19: FALSE | G19: FALSE | H19: FALSE | I19: TRUE | J19: TRUE | K19: TRUE | L19: FALSE | M19: FALSE | N19: FALSE | O19: FALSE | P19: FALSE | Q19: TRUE | R19: TRUE | S19: FALSE | T19: FALSE | U19: FALSE | V19: FALSE | W19: FALSE | X19: FALSE | Y19: FALSE | Z19: FALSE | AA19: FALSE | AB19: FALSE | AC19: FALSE | AD19: FALSE | AE19: FALSE | AF19: FALSE | AH19: =30 -> 30 | AI19: =COUNTIF(C19:AF19, TRUE) -> 7 | AJ19: =IFERROR(__xludf.DUMMYFUNCTION("SPARKLINE(AI19/AH19, {""charttype"",""bar"";""max"",1;""color1"",""#90EE90""})"),"")
B21: Progress | C21: =COUNTIF(C10:C19, TRUE)/COUNTA(C10:C19) -> 0.9 | D21: =COUNTIF(D10:D19, TRUE)/COUNTA(D10:D19) -> 0.7 | E21: =COUNTIF(E10:E19, TRUE)/COUNTA(E10:E19) -> 0.8 | F21: =COUNTIF(F10:F19, TRUE)/COUNTA(F10:F19) -> 0.4 | G21: =COUNTIF(G10:G19, TRUE)/COUNTA(G10:G19) -> 0.4 | H21: =COUNTIF(H10:H19, TRUE)/COUNTA(H10:H19) -> 0.4 | I21: =COUNTIF(I10:I19, TRUE)/COUNTA(I10:I19) -> 0.7 | J21: =COUNTIF(J10:J19, TRUE)/COUNTA(J10:J19) -> 0.6 | ... AF21: =COUNTIF(AF10:AF19, TRUE)/COUNTA(AF10:AF19) -> 0.6
B22: Done | C22: =COUNTIF(C10:C19, TRUE) -> 9 | D22: =COUNTIF(D10:D19, TRUE) -> 7 | E22: =COUNTIF(E10:E19, TRUE) -> 8 | F22: =COUNTIF(F10:F19, TRUE) -> 4 | G22: =COUNTIF(G10:G19, TRUE) -> 4 | H22: =COUNTIF(H10:H19, TRUE) -> 4 | I22: =COUNTIF(I10:I19, TRUE) -> 7 | J22: =COUNTIF(J10:J19, TRUE) -> 6 | ... AF22: =COUNTIF(AF10:AF19, TRUE) -> 6
B23: Not Done | C23: =COUNTIF(C10:C19, FALSE) -> 1 | D23: =COUNTIF(D10:D19, FALSE) -> 3 | E23: =COUNTIF(E10:E19, FALSE) -> 2 | F23: =COUNTIF(F10:F19, FALSE) -> 6 | G23: =COUNTIF(G10:G19, FALSE) -> 6 | H23: =COUNTIF(H10:H19, FALSE) -> 6 | I23: =COUNTIF(I10:I19, FALSE) -> 3 | J23: =COUNTIF(J10:J19, FALSE) -> 4 | ... AF23: =COUNTIF(AF10:AF19, FALSE) -> 4
C33: Mental State
B34: Mood | C34: 9 | D34: 4 | E34: 6 | F34: 9 | G34: 9 | H34: 7 | I34: 9 | J34: 8 | K34: 6 | L34: 6 | M34: 4 | N34: 7 | O34: 3 | P34: 7 | Q34: 2 | R34: 5
B35: Motivation | C35: 7 | D35: 8 | E35: 8 | F35: 8 | I35: 5 | J35: 5 | K35: 9 | L35: 7 | M35: 5 | N35: 7 | O35: 8 | P35: 5 | Q35: 5 | R35: 8 | S35: 8
C36: =(C35+C34)/20 -> 0.8 | D36: =(D35+D34)/20 -> 0.6 | E36: =(E35+E34)/20 -> 0.7 | F36: =(F35+F34)/20 -> 0.85 | G36: =(G35+G34)/20 -> 0.45 | H36: =(H35+H34)/20 -> 0.35 | I36: =(I35+I34)/20 -> 0.7 | J36: =(J35+J34)/20 -> 0.65 | ... AF36: =(AF35+AF34)/20 -> 0

Sheet Jan
B3: January | J3: Number of habits | P3: Completed habits | V3: Progress | AB3: Progress in %
J4: =COUNTA($B$10:$B$19) -> 0 | P4: =COUNTIF($C$10:$AF$19, TRUE) -> 0 | V4: =IFERROR(__xludf.DUMMYFUNCTION("SPARKLINE(AB4, {""charttype"",""bar"";""max"",1;""color1"",""#90EE90""})"),"") | AB4: =(P4)/(COUNTA($C$10:$C$19)*COUNTA($C$10:$AG$10)) -> 0
B7: My Habits | C7: Week 1 | J7: Week 2 | Q7: Week 3 | X7: Week 4 | AI7: Analysis
C8: Th | D8: Fr | E8: Sa | F8: Su | G8: Mo | H8: Tu | I8: We | J8: Th | K8: Fr | L8: Sa | M8: Su | N8: Mo | O8: Tu | P8: We | Q8: Th | R8: Fr | S8: Sa | T8: Su | U8: Mo | V8: Tu | W8: We | X8: Th | Y8: Fr | Z8: Sa | AA8: Su | AB8: Mo | AC8: Tu | AD8: We | AE8: Th | AF8: Fr | AG8: Sa
C9: 1 | D9: 2 | E9: 3 | F9: 4 | G9: 5 | H9: 6 | I9: 7 | J9: 8 | K9: 9 | L9: 10 | M9: 11 | N9: 12 | O9: 13 | P9: 14 | Q9: 15 | R9: 16 | S9: 17 | T9: 18 | U9: 19 | V9: 20 | W9: 21 | X9: 22 | Y9: 23 | Z9: 24 | AA9: 25 | AB9: 26 | AC9: 27 | AD9: 28 | AE9: 29 | AF9: 30 | AG9: 31 | AI9: Goal | AJ9: Actual | AK9: Progress
C10: FALSE | D10: FALSE | E10: FALSE | F10: FALSE | G10: FALSE | H10: FALSE | I10: FALSE | J10: FALSE | K10: FALSE | L10: FALSE | M10: FALSE | N10: FALSE | O10: FALSE | P10: FALSE | Q10: FALSE | R10: FALSE | S10: FALSE | T10: FALSE | U10: FALSE | V10: FALSE | W10: FALSE | X10: FALSE | Y10: FALSE | Z10: FALSE | AA10: FALSE | AB10: FALSE | AC10: FALSE | AD10: FALSE | AE10: FALSE | AF10: FALSE | AG10: FALSE | AI10: =31 -> 31 | AJ10: =COUNTIF(C10:AG10, TRUE) -> 0 | AK10: =IFERROR(__xludf.DUMMYFUNCTION("SPARKLINE(AJ10/AI10, {""charttype"",""bar"";""max"",1;""color1"",""#90EE90""})"),"")
C11: FALSE | D11: FALSE | E11: FALSE | F11: FALSE | G11: FALSE | H11: FALSE | I11: FALSE | J11: FALSE | K11: FALSE | L11: FALSE | M11: FALSE | N11: FALSE | O11: FALSE | P11: FALSE | Q11: FALSE | R11: FALSE | S11: FALSE | T11: FALSE | U11: FALSE | V11: FALSE | W11: FALSE | X11: FALSE | Y11: FALSE | Z11: FALSE | AA11: FALSE | AB11: FALSE | AC11: FALSE | AD11: FALSE | AE11: FALSE | AF11: FALSE | AG11: FALSE | AI11: =31 -> 31 | AJ11: =COUNTIF(C11:AG11, TRUE) -> 0 | AK11: =IFERROR(__xludf.DUMMYFUNCTION("SPARKLINE(AJ11/AI11, {""charttype"",""bar"";""max"",1;""color1"",""#90EE90""})"),"")
C12: FALSE | D12: FALSE | E12: FALSE | F12: FALSE | G12: FALSE | H12: FALSE | I12: FALSE | J12: FALSE | K12: FALSE | L12: FALSE | M12: FALSE | N12: FALSE | O12: FALSE | P12: FALSE | Q12: FALSE | R12: FALSE | S12: FALSE | T12: FALSE | U12: FALSE | V12: FALSE | W12: FALSE | X12: FALSE | Y12: FALSE | Z12: FALSE | AA12: FALSE | AB12: FALSE | AC12: FALSE | AD12: FALSE | AE12: FALSE | AF12: FALSE | AG12: FALSE | AI12: =31 -> 31 | AJ12: =COUNTIF(C12:AG12, TRUE) -> 0 | AK12: =IFERROR(__xludf.DUMMYFUNCTION("SPARKLINE(AJ12/AI12, {""charttype"",""bar"";""max"",1;""color1"",""#90EE90""})"),"")
C13: FALSE | D13: FALSE | E13: FALSE | F13: FALSE | G13: FALSE | H13: FALSE | I13: FALSE | J13: FALSE | K13: FALSE | L13: FALSE | M13: FALSE | N13: FALSE | O13: FALSE | P13: FALSE | Q13: FALSE | R13: FALSE | S13: FALSE | T13: FALSE | U13: FALSE | V13: FALSE | W13: FALSE | X13: FALSE | Y13: FALSE | Z13: FALSE | AA13: FALSE | AB13: FALSE | AC13: FALSE | AD13: FALSE | AE13: FALSE | AF13: FALSE | AG13: FALSE | AI13: =31 -> 31 | AJ13: =COUNTIF(C13:AG13, TRUE) -> 0 | AK13: =IFERROR(__xludf.DUMMYFUNCTION("SPARKLINE(AJ13/AI13, {""charttype"",""bar"";""max"",1;""color1"",""#90EE90""})"),"")
C14: FALSE | D14: FALSE | E14: FALSE | F14: FALSE | G14: FALSE | H14: FALSE | I14: FALSE | J14: FALSE | K14: FALSE | L14: FALSE | M14: FALSE | N14: FALSE | O14: FALSE | P14: FALSE | Q14: FALSE | R14: FALSE | S14: FALSE | T14: FALSE | U14: FALSE | V14: FALSE | W14: FALSE | X14: FALSE | Y14: FALSE | Z14: FALSE | AA14: FALSE | AB14: FALSE | AC14: FALSE | AD14: FALSE | AE14: FALSE | AF14: FALSE | AG14: FALSE | AI14: =31 -> 31 | AJ14: =COUNTIF(C14:AG14, TRUE) -> 0 | AK14: =IFERROR(__xludf.DUMMYFUNCTION("SPARKLINE(AJ14/AI14, {""charttype"",""bar"";""max"",1;""color1"",""#90EE90""})"),"")
C15: FALSE | D15: FALSE | E15: FALSE | F15: FALSE | G15: FALSE | H15: FALSE | I15: FALSE | J15: FALSE | K15: FALSE | L15: FALSE | M15: FALSE | N15: FALSE | O15: FALSE | P15: FALSE | Q15: FALSE | R15: FALSE | S15: FALSE | T15: FALSE | U15: FALSE | V15: FALSE | W15: FALSE | X15: FALSE | Y15: FALSE | Z15: FALSE | AA15: FALSE | AB15: FALSE | AC15: FALSE | AD15: FALSE | AE15: FALSE | AF15: FALSE | AG15: FALSE | AI15: =31 -> 31 | AJ15: =COUNTIF(C15:AG15, TRUE) -> 0 | AK15: =IFERROR(__xludf.DUMMYFUNCTION("SPARKLINE(AJ15/AI15, {""charttype"",""bar"";""max"",1;""color1"",""#90EE90""})"),"")
C16: FALSE | D16: FALSE | E16: FALSE | F16: FALSE | G16: FALSE | H16: FALSE | I16: FALSE | J16: FALSE | K16: FALSE | L16: FALSE | M16: FALSE | N16: FALSE | O16: FALSE | P16: FALSE | Q16: FALSE | R16: FALSE | S16: FALSE | T16: FALSE | U16: FALSE | V16: FALSE | W16: FALSE | X16: FALSE | Y16: FALSE | Z16: FALSE | AA16: FALSE | AB16: FALSE | AC16: FALSE | AD16: FALSE | AE16: FALSE | AF16: FALSE | AG16: FALSE | AI16: =31 -> 31 | AJ16: =COUNTIF(C16:AG16, TRUE) -> 0 | AK16: =IFERROR(__xludf.DUMMYFUNCTION("SPARKLINE(AJ16/AI16, {""charttype"",""bar"";""max"",1;""color1"",""#90EE90""})"),"")
C17: FALSE | D17: FALSE | E17: FALSE | F17: FALSE | G17: FALSE | H17: FALSE | I17: FALSE | J17: FALSE | K17: FALSE | L17: FALSE | M17: FALSE | N17: FALSE | O17: FALSE | P17: FALSE | Q17: FALSE | R17: FALSE | S17: FALSE | T17: FALSE | U17: FALSE | V17: FALSE | W17: FALSE | X17: FALSE | Y17: FALSE | Z17: FALSE | AA17: FALSE | AB17: FALSE | AC17: FALSE | AD17: FALSE | AE17: FALSE | AF17: FALSE | AG17: FALSE | AI17: =31 -> 31 | AJ17: =COUNTIF(C17:AG17, TRUE) -> 0 | AK17: =IFERROR(__xludf.DUMMYFUNCTION("SPARKLINE(AJ17/AI17, {""charttype"",""bar"";""max"",1;""color1"",""#90EE90""})"),"")
C18: FALSE | D18: FALSE | E18: FALSE | F18: FALSE | G18: FALSE | H18: FALSE | I18: FALSE | J18: FALSE | K18: FALSE | L18: FALSE | M18: FALSE | N18: FALSE | O18: FALSE | P18: FALSE | Q18: FALSE | R18: FALSE | S18: FALSE | T18: FALSE | U18: FALSE | V18: FALSE | W18: FALSE | X18: FALSE | Y18: FALSE | Z18: FALSE | AA18: FALSE | AB18: FALSE | AC18: FALSE | AD18: FALSE | AE18: FALSE | AF18: FALSE | AG18: FALSE | AI18: =31 -> 31 | AJ18: =COUNTIF(C18:AG18, TRUE) -> 0 | AK18: =IFERROR(__xludf.DUMMYFUNCTION("SPARKLINE(AJ18/AI18, {""charttype"",""bar"";""max"",1;""color1"",""#90EE90""})"),"")
C19: FALSE | D19: FALSE | E19: FALSE | F19: FALSE | G19: FALSE | H19: FALSE | I19: FALSE | J19: FALSE | K19: FALSE | L19: FALSE | M19: FALSE | N19: FALSE | O19: FALSE | P19: FALSE | Q19: FALSE | R19: FALSE | S19: FALSE | T19: FALSE | U19: FALSE | V19: FALSE | W19: FALSE | X19: FALSE | Y19: FALSE | Z19: FALSE | AA19: FALSE | AB19: FALSE | AC19: FALSE | AD19: FALSE | AE19: FALSE | AF19: FALSE | AG19: FALSE | AI19: =31 -> 31 | AJ19: =COUNTIF(C19:AG19, TRUE) -> 0 | AK19: =IFERROR(__xludf.DUMMYFUNCTION("SPARKLINE(AJ19/AI19, {""charttype"",""bar"";""max"",1;""color1"",""#90EE90""})"),"")
B21: Progress | C21: =COUNTIF(C10:C19, TRUE)/COUNTA(C10:C19) -> 0 | D21: =COUNTIF(D10:D19, TRUE)/COUNTA(D10:D19) -> 0 | E21: =COUNTIF(E10:E19, TRUE)/COUNTA(E10:E19) -> 0 | F21: =COUNTIF(F10:F19, TRUE)/COUNTA(F10:F19) -> 0 | G21: =COUNTIF(G10:G19, TRUE)/COUNTA(G10:G19) -> 0 | H21: =COUNTIF(H10:H19, TRUE)/COUNTA(H10:H19) -> 0 | I21: =COUNTIF(I10:I19, TRUE)/COUNTA(I10:I19) -> 0 | J21: =COUNTIF(J10:J19, TRUE)/COUNTA(J10:J19) -> 0 | ... AG21: =COUNTIF(AG10:AG19, TRUE)/COUNTA(AG10:AG19) -> 0
B22: Done | C22: =COUNTIF(C10:C19, TRUE) -> 0 | D22: =COUNTIF(D10:D19, TRUE) -> 0 | E22: =COUNTIF(E10:E19, TRUE) -> 0 | F22: =COUNTIF(F10:F19, TRUE) -> 0 | G22: =COUNTIF(G10:G19, TRUE) -> 0 | H22: =COUNTIF(H10:H19, TRUE) -> 0 | I22: =COUNTIF(I10:I19, TRUE) -> 0 | J22: =COUNTIF(J10:J19, TRUE) -> 0 | ... AG22: =COUNTIF(AG10:AG19, TRUE) -> 0
B23: Not Done | C23: =COUNTIF(C10:C19, FALSE) -> 10 | D23: =COUNTIF(D10:D19, FALSE) -> 10 | E23: =COUNTIF(E10:E19, FALSE) -> 10 | F23: =COUNTIF(F10:F19, FALSE) -> 10 | G23: =COUNTIF(G10:G19, FALSE) -> 10 | H23: =COUNTIF(H10:H19, FALSE) -> 10 | I23: =COUNTIF(I10:I19, FALSE) -> 10 | J23: =COUNTIF(J10:J19, FALSE) -> 10 | ... AG23: =COUNTIF(AG10:AG19, FALSE) -> 10
C33: Mental State
B34: Mood
B35: Motivation
C36: =(C35+C34)/20 -> 0 | D36: =(D35+D34)/20 -> 0 | E36: =(E35+E34)/20 -> 0 | F36: =(F35+F34)/20 -> 0 | G36: =(G35+G34)/20 -> 0 | H36: =(H35+H34)/20 -> 0 | I36: =(I35+I34)/20 -> 0 | J36: =(J35+J34)/20 -> 0 | ... AG36: =(AG35+AG34)/20 -> 0

Sheet Feb
B3: February | J3: Number of habits | P3: Completed habits | V3: Progress | AB3: Progress in %
J4: =COUNTA($B$10:$B$19) -> 0 | P4: =COUNTIF($C$10:$AD$19, TRUE) -> 0 | V4: =IFERROR(__xludf.DUMMYFUNCTION("SPARKLINE(AB4, {""charttype"",""bar"";""max"",1;""color1"",""#90EE90""})"),"") | AB4: =(P4)/(COUNTA($C$10:$C$19)*COUNTA($C$10:$AD$10)) -> 0
B7: My Habits | C7: Week 1 | J7: Week 2 | Q7: Week 3 | X7: Week 4 | AF7: Analysis
C8: Su | D8: Mo | E8: Tu | F8: We | G8: Th | H8: Fr | I8: Sa | J8: Su | K8: Mo | L8: Tu | M8: We | N8: Th | O8: Fr | P8: Sa | Q8: Su | R8: Mo | S8: Tu | T8: We | U8: Th | V8: Fr | W8: Sa | X8: Su | Y8: Mo | Z8: Tu | AA8: We | AB8: Th | AC8: Fr | AD8: Sa
C9: 1 | D9: 2 | E9: 3 | F9: 4 | G9: 5 | H9: 6 | I9: 7 | J9: 8 | K9: 9 | L9: 10 | M9: 11 | N9: 12 | O9: 13 | P9: 14 | Q9: 15 | R9: 16 | S9: 17 | T9: 18 | U9: 19 | V9: 20 | W9: 21 | X9: 22 | Y9: 23 | Z9: 24 | AA9: 25 | AB9: 26 | AC9: 27 | AD9: 28 | AF9: Goal | AG9: Actual | AH9: Progress
C10: FALSE | D10: FALSE | E10: FALSE | F10: FALSE | G10: FALSE | H10: FALSE | I10: FALSE | J10: FALSE | K10: FALSE | L10: FALSE | M10: FALSE | N10: FALSE | O10: FALSE | P10: FALSE | Q10: FALSE | R10: FALSE | S10: FALSE | T10: FALSE | U10: FALSE | V10: FALSE | W10: FALSE | X10: FALSE | Y10: FALSE | Z10: FALSE | AA10: FALSE | AB10: FALSE | AC10: FALSE | AD10: FALSE | AF10: 28 | AG10: =COUNTIF(C10:AD10, TRUE) -> 0 | AH10: =IFERROR(__xludf.DUMMYFUNCTION("SPARKLINE(AG10/AF10, {""charttype"",""bar"";""max"",1;""color1"",""#90EE90""})"),"")
C11: FALSE | D11: FALSE | E11: FALSE | F11: FALSE | G11: FALSE | H11: FALSE | I11: FALSE | J11: FALSE | K11: FALSE | L11: FALSE | M11: FALSE | N11: FALSE | O11: FALSE | P11: FALSE | Q11: FALSE | R11: FALSE | S11: FALSE | T11: FALSE | U11: FALSE | V11: FALSE | W11: FALSE | X11: FALSE | Y11: FALSE | Z11: FALSE | AA11: FALSE | AB11: FALSE | AC11: FALSE | AD11: FALSE | AF11: 28 | AG11: =COUNTIF(C11:AD11, TRUE) -> 0 | AH11: =IFERROR(__xludf.DUMMYFUNCTION("SPARKLINE(AG11/AF11, {""charttype"",""bar"";""max"",1;""color1"",""#90EE90""})"),"")
C12: FALSE | D12: FALSE | E12: FALSE | F12: FALSE | G12: FALSE | H12: FALSE | I12: FALSE | J12: FALSE | K12: FALSE | L12: FALSE | M12: FALSE | N12: FALSE | O12: FALSE | P12: FALSE | Q12: FALSE | R12: FALSE | S12: FALSE | T12: FALSE | U12: FALSE | V12: FALSE | W12: FALSE | X12: FALSE | Y12: FALSE | Z12: FALSE | AA12: FALSE | AB12: FALSE | AC12: FALSE | AD12: FALSE | AF12: 28 | AG12: =COUNTIF(C12:AD12, TRUE) -> 0 | AH12: =IFERROR(__xludf.DUMMYFUNCTION("SPARKLINE(AG12/AF12, {""charttype"",""bar"";""max"",1;""color1"",""#90EE90""})"),"")
C13: FALSE | D13: FALSE | E13: FALSE | F13: FALSE | G13: FALSE | H13: FALSE | I13: FALSE | J13: FALSE | K13: FALSE | L13: FALSE | M13: FALSE | N13: FALSE | O13: FALSE | P13: FALSE | Q13: FALSE | R13: FALSE | S13: FALSE | T13: FALSE | U13: FALSE | V13: FALSE | W13: FALSE | X13: FALSE | Y13: FALSE | Z13: FALSE | AA13: FALSE | AB13: FALSE | AC13: FALSE | AD13: FALSE | AF13: 28 | AG13: =COUNTIF(C13:AD13, TRUE) -> 0 | AH13: =IFERROR(__xludf.DUMMYFUNCTION("SPARKLINE(AG13/AF13, {""charttype"",""bar"";""max"",1;""color1"",""#90EE90""})"),"")
C14: FALSE | D14: FALSE | E14: FALSE | F14: FALSE | G14: FALSE | H14: FALSE | I14: FALSE | J14: FALSE | K14: FALSE | L14: FALSE | M14: FALSE | N14: FALSE | O14: FALSE | P14: FALSE | Q14: FALSE | R14: FALSE | S14: FALSE | T14: FALSE | U14: FALSE | V14: FALSE | W14: FALSE | X14: FALSE | Y14: FALSE | Z14: FALSE | AA14: FALSE | AB14: FALSE | AC14: FALSE | AD14: FALSE | AF14: 28 | AG14: =COUNTIF(C14:AD14, TRUE) -> 0 | AH14: =IFERROR(__xludf.DUMMYFUNCTION("SPARKLINE(AG14/AF14, {""charttype"",""bar"";""max"",1;""color1"",""#90EE90""})"),"")
C15: FALSE | D15: FALSE | E15: FALSE | F15: FALSE | G15: FALSE | H15: FALSE | I15: FALSE | J15: FALSE | K15: FALSE | L15: FALSE | M15: FALSE | N15: FALSE | O15: FALSE | P15: FALSE | Q15: FALSE | R15: FALSE | S15: FALSE | T15: FALSE | U15: FALSE | V15: FALSE | W15: FALSE | X15: FALSE | Y15: FALSE | Z15: FALSE | AA15: FALSE | AB15: FALSE | AC15: FALSE | AD15: FALSE | AF15: 28 | AG15: =COUNTIF(C15:AD15, TRUE) -> 0 | AH15: =IFERROR(__xludf.DUMMYFUNCTION("SPARKLINE(AG15/AF15, {""charttype"",""bar"";""max"",1;""color1"",""#90EE90""})"),"")
C16: FALSE | D16: FALSE | E16: FALSE | F16: FALSE | G16: FALSE | H16: FALSE | I16: FALSE | J16: FALSE | K16: FALSE | L16: FALSE | M16: FALSE | N16: FALSE | O16: FALSE | P16: FALSE | Q16: FALSE | R16: FALSE | S16: FALSE | T16: FALSE | U16: FALSE | V16: FALSE | W16: FALSE | X16: FALSE | Y16: FALSE | Z16: FALSE | AA16: FALSE | AB16: FALSE | AC16: FALSE | AD16: FALSE | AF16: 28 | AG16: =COUNTIF(C16:AD16, TRUE) -> 0 | AH16: =IFERROR(__xludf.DUMMYFUNCTION("SPARKLINE(AG16/AF16, {""charttype"",""bar"";""max"",1;""color1"",""#90EE90""})"),"")
C17: FALSE | D17: FALSE | E17: FALSE | F17: FALSE | G17: FALSE | H17: FALSE | I17: FALSE | J17: FALSE | K17: FALSE | L17: FALSE | M17: FALSE | N17: FALSE | O17: FALSE | P17: FALSE | Q17: FALSE | R17: FALSE | S17: FALSE | T17: FALSE | U17: FALSE | V17: FALSE | W17: FALSE | X17: FALSE | Y17: FALSE | Z17: FALSE | AA17: FALSE | AB17: FALSE | AC17: FALSE | AD17: FALSE | AF17: 28 | AG17: =COUNTIF(C17:AD17, TRUE) -> 0 | AH17: =IFERROR(__xludf.DUMMYFUNCTION("SPARKLINE(AG17/AF17, {""charttype"",""bar"";""max"",1;""color1"",""#90EE90""})"),"")
C18: FALSE | D18: FALSE | E18: FALSE | F18: FALSE | G18: FALSE | H18: FALSE | I18: FALSE | J18: FALSE | K18: FALSE | L18: FALSE | M18: FALSE | N18: FALSE | O18: FALSE | P18: FALSE | Q18: FALSE | R18: FALSE | S18: FALSE | T18: FALSE | U18: FALSE | V18: FALSE | W18: FALSE | X18: FALSE | Y18: FALSE | Z18: FALSE | AA18: FALSE | AB18: FALSE | AC18: FALSE | AD18: FALSE | AF18: 28 | AG18: =COUNTIF(C18:AD18, TRUE) -> 0 | AH18: =IFERROR(__xludf.DUMMYFUNCTION("SPARKLINE(AG18/AF18, {""charttype"",""bar"";""max"",1;""color1"",""#90EE90""})"),"")
C19: FALSE | D19: FALSE | E19: FALSE | F19: FALSE | G19: FALSE | H19: FALSE | I19: FALSE | J19: FALSE | K19: FALSE | L19: FALSE | M19: FALSE | N19: FALSE | O19: FALSE | P19: FALSE | Q19: FALSE | R19: FALSE | S19: FALSE | T19: FALSE | U19: FALSE | V19: FALSE | W19: FALSE | X19: FALSE | Y19: FALSE | Z19: FALSE | AA19: FALSE | AB19: FALSE | AC19: FALSE | AD19: FALSE | AF19: 28 | AG19: =COUNTIF(C19:AD19, TRUE) -> 0 | AH19: =IFERROR(__xludf.DUMMYFUNCTION("SPARKLINE(AG19/AF19, {""charttype"",""bar"";""max"",1;""color1"",""#90EE90""})"),"")
B21: Progress | C21: =COUNTIF(C10:C19, TRUE)/COUNTA(C10:C19) -> 0 | D21: =COUNTIF(D10:D19, TRUE)/COUNTA(D10:D19) -> 0 | E21: =COUNTIF(E10:E19, TRUE)/COUNTA(E10:E19) -> 0 | F21: =COUNTIF(F10:F19, TRUE)/COUNTA(F10:F19) -> 0 | G21: =COUNTIF(G10:G19, TRUE)/COUNTA(G10:G19) -> 0 | H21: =COUNTIF(H10:H19, TRUE)/COUNTA(H10:H19) -> 0 | I21: =COUNTIF(I10:I19, TRUE)/COUNTA(I10:I19) -> 0 | J21: =COUNTIF(J10:J19, TRUE)/COUNTA(J10:J19) -> 0 | ... AD21: =COUNTIF(AD10:AD19, TRUE)/COUNTA(AD10:AD19) -> 0
B22: Done | C22: =COUNTIF(C10:C19, TRUE) -> 0 | D22: =COUNTIF(D10:D19, TRUE) -> 0 | E22: =COUNTIF(E10:E19, TRUE) -> 0 | F22: =COUNTIF(F10:F19, TRUE) -> 0 | G22: =COUNTIF(G10:G19, TRUE) -> 0 | H22: =COUNTIF(H10:H19, TRUE) -> 0 | I22: =COUNTIF(I10:I19, TRUE) -> 0 | J22: =COUNTIF(J10:J19, TRUE) -> 0 | ... AD22: =COUNTIF(AD10:AD19, TRUE) -> 0
B23: Not Done | C23: =COUNTIF(C10:C19, FALSE) -> 10 | D23: =COUNTIF(D10:D19, FALSE) -> 10 | E23: =COUNTIF(E10:E19, FALSE) -> 10 | F23: =COUNTIF(F10:F19, FALSE) -> 10 | G23: =COUNTIF(G10:G19, FALSE) -> 10 | H23: =COUNTIF(H10:H19, FALSE) -> 10 | I23: =COUNTIF(I10:I19, FALSE) -> 10 | J23: =COUNTIF(J10:J19, FALSE) -> 10 | ... AD23: =COUNTIF(AD10:AD19, FALSE) -> 10
B33: Mental State
B34: Mood
B35: Motivation
C36: =(C35+C34)/20 -> 0 | D36: =(D35+D34)/20 -> 0 | E36: =(E35+E34)/20 -> 0 | F36: =(F35+F34)/20 -> 0 | G36: =(G35+G34)/20 -> 0 | H36: =(H35+H34)/20 -> 0 | I36: =(I35+I34)/20 -> 0 | J36: =(J35+J34)/20 -> 0 | ... AF36: =(AF35+AF34)/20 -> 0

Sheet Mar
B3: March | J3: Number of habits | P3: Completed habits | V3: Progress | AB3: Progress in %
J4: =COUNTA($B$10:$B$19) -> 0 | P4: =COUNTIF($C$10:$AF$19, TRUE) -> 0 | V4: =IFERROR(__xludf.DUMMYFUNCTION("SPARKLINE(AB4, {""charttype"",""bar"";""max"",1;""color1"",""#90EE90""})"),"") | AB4: =(P4)/(COUNTA($C$10:$C$19)*COUNTA($C$10:$AG$10)) -> 0
B7: My Habits | C7: Week 1 | J7: Week 2 | Q7: Week 3 | X7: Week 4 | AI7: Analysis
C8: Su | D8: Mo | E8: Tu | F8: We | G8: Th | H8: Fr | I8: Sa | J8: Su | K8: Mo | L8: Tu | M8: We | N8: Th | O8: Fr | P8: Sa | Q8: Su | R8: Mo | S8: Tu | T8: We | U8: Th | V8: Fr | W8: Sa | X8: Su | Y8: Mo | Z8: Tu | AA8: We | AB8: Th | AC8: Fr | AD8: Sa | AE8: Su | AF8: Mo | AG8: Tu
C9: 1 | D9: 2 | E9: 3 | F9: 4 | G9: 5 | H9: 6 | I9: 7 | J9: 8 | K9: 9 | L9: 10 | M9: 11 | N9: 12 | O9: 13 | P9: 14 | Q9: 15 | R9: 16 | S9: 17 | T9: 18 | U9: 19 | V9: 20 | W9: 21 | X9: 22 | Y9: 23 | Z9: 24 | AA9: 25 | AB9: 26 | AC9: 27 | AD9: 28 | AE9: 29 | AF9: 30 | AG9: 31 | AI9: Goal | AJ9: Actual | AK9: Progress
C10: FALSE | D10: FALSE | E10: FALSE | F10: FALSE | G10: FALSE | H10: FALSE | I10: FALSE | J10: FALSE | K10: FALSE | L10: FALSE | M10: FALSE | N10: FALSE | O10: FALSE | P10: FALSE | Q10: FALSE | R10: FALSE | S10: FALSE | T10: FALSE | U10: FALSE | V10: FALSE | W10: FALSE | X10: FALSE | Y10: FALSE | Z10: FALSE | AA10: FALSE | AB10: FALSE | AC10: FALSE | AD10: FALSE | AE10: FALSE | AF10: FALSE | AG10: FALSE | AI10: =31 -> 31 | AJ10: =COUNTIF(C10:AG10, TRUE) -> 0 | AK10: =IFERROR(__xludf.DUMMYFUNCTION("SPARKLINE(AJ10/AI10, {""charttype"",""bar"";""max"",1;""color1"",""#90EE90""})"),"")
C11: FALSE | D11: FALSE | E11: FALSE | F11: FALSE | G11: FALSE | H11: FALSE | I11: FALSE | J11: FALSE | K11: FALSE | L11: FALSE | M11: FALSE | N11: FALSE | O11: FALSE | P11: FALSE | Q11: FALSE | R11: FALSE | S11: FALSE | T11: FALSE | U11: FALSE | V11: FALSE | W11: FALSE | X11: FALSE | Y11: FALSE | Z11: FALSE | AA11: FALSE | AB11: FALSE | AC11: FALSE | AD11: FALSE | AE11: FALSE | AF11: FALSE | AG11: FALSE | AI11: =31 -> 31 | AJ11: =COUNTIF(C11:AG11, TRUE) -> 0 | AK11: =IFERROR(__xludf.DUMMYFUNCTION("SPARKLINE(AJ11/AI11, {""charttype"",""bar"";""max"",1;""color1"",""#90EE90""})"),"")
C12: FALSE | D12: FALSE | E12: FALSE | F12: FALSE | G12: FALSE | H12: FALSE | I12: FALSE | J12: FALSE | K12: FALSE | L12: FALSE | M12: FALSE | N12: FALSE | O12: FALSE | P12: FALSE | Q12: FALSE | R12: FALSE | S12: FALSE | T12: FALSE | U12: FALSE | V12: FALSE | W12: FALSE | X12: FALSE | Y12: FALSE | Z12: FALSE | AA12: FALSE | AB12: FALSE | AC12: FALSE | AD12: FALSE | AE12: FALSE | AF12: FALSE | AG12: FALSE | AI12: =31 -> 31 | AJ12: =COUNTIF(C12:AG12, TRUE) -> 0 | AK12: =IFERROR(__xludf.DUMMYFUNCTION("SPARKLINE(AJ12/AI12, {""charttype"",""bar"";""max"",1;""color1"",""#90EE90""})"),"")
C13: FALSE | D13: FALSE | E13: FALSE | F13: FALSE | G13: FALSE | H13: FALSE | I13: FALSE | J13: FALSE | K13: FALSE | L13: FALSE | M13: FALSE | N13: FALSE | O13: FALSE | P13: FALSE | Q13: FALSE | R13: FALSE | S13: FALSE | T13: FALSE | U13: FALSE | V13: FALSE | W13: FALSE | X13: FALSE | Y13: FALSE | Z13: FALSE | AA13: FALSE | AB13: FALSE | AC13: FALSE | AD13: FALSE | AE13: FALSE | AF13: FALSE | AG13: FALSE | AI13: =31 -> 31 | AJ13: =COUNTIF(C13:AG13, TRUE) -> 0 | AK13: =IFERROR(__xludf.DUMMYFUNCTION("SPARKLINE(AJ13/AI13, {""charttype"",""bar"";""max"",1;""color1"",""#90EE90""})"),"")
C14: FALSE | D14: FALSE | E14: FALSE | F14: FALSE | G14: FALSE | H14: FALSE | I14: FALSE | J14: FALSE | K14: FALSE | L14: FALSE | M14: FALSE | N14: FALSE | O14: FALSE | P14: FALSE | Q14: FALSE | R14: FALSE | S14: FALSE | T14: FALSE | U14: FALSE | V14: FALSE | W14: FALSE | X14: FALSE | Y14: FALSE | Z14: FALSE | AA14: FALSE | AB14: FALSE | AC14: FALSE | AD14: FALSE | AE14: FALSE | AF14: FALSE | AG14: FALSE | AI14: =31 -> 31 | AJ14: =COUNTIF(C14:AG14, TRUE) -> 0 | AK14: =IFERROR(__xludf.DUMMYFUNCTION("SPARKLINE(AJ14/AI14, {""charttype"",""bar"";""max"",1;""color1"",""#90EE90""})"),"")
C15: FALSE | D15: FALSE | E15: FALSE | F15: FALSE | G15: FALSE | H15: FALSE | I15: FALSE | J15: FALSE | K15: FALSE | L15: FALSE | M15: FALSE | N15: FALSE | O15: FALSE | P15: FALSE | Q15: FALSE | R15: FALSE | S15: FALSE | T15: FALSE | U15: FALSE | V15: FALSE | W15: FALSE | X15: FALSE | Y15: FALSE | Z15: FALSE | AA15: FALSE | AB15: FALSE | AC15: FALSE | AD15: FALSE | AE15: FALSE | AF15: FALSE | AG15: FALSE | AI15: =31 -> 31 | AJ15: =COUNTIF(C15:AG15, TRUE) -> 0 | AK15: =IFERROR(__xludf.DUMMYFUNCTION("SPARKLINE(AJ15/AI15, {""charttype"",""bar"";""max"",1;""color1"",""#90EE90""})"),"")
C16: FALSE | D16: FALSE | E16: FALSE | F16: FALSE | G16: FALSE | H16: FALSE | I16: FALSE | J16: FALSE | K16: FALSE | L16: FALSE | M16: FALSE | N16: FALSE | O16: FALSE | P16: FALSE | Q16: FALSE | R16: FALSE | S16: FALSE | T16: FALSE | U16: FALSE | V16: FALSE | W16: FALSE | X16: FALSE | Y16: FALSE | Z16: FALSE | AA16: FALSE | AB16: FALSE | AC16: FALSE | AD16: FALSE | AE16: FALSE | AF16: FALSE | AG16: FALSE | AI16: =31 -> 31 | AJ16: =COUNTIF(C16:AG16, TRUE) -> 0 | AK16: =IFERROR(__xludf.DUMMYFUNCTION("SPARKLINE(AJ16/AI16, {""charttype"",""bar"";""max"",1;""color1"",""#90EE90""})"),"")
C17: FALSE | D17: FALSE | E17: FALSE | F17: FALSE | G17: FALSE | H17: FALSE | I17: FALSE | J17: FALSE | K17: FALSE | L17: FALSE | M17: FALSE | N17: FALSE | O17: FALSE | P17: FALSE | Q17: FALSE | R17: FALSE | S17: FALSE | T17: FALSE | U17: FALSE | V17: FALSE | W17: FALSE | X17: FALSE | Y17: FALSE | Z17: FALSE | AA17: FALSE | AB17: FALSE | AC17: FALSE | AD17: FALSE | AE17: FALSE | AF17: FALSE | AG17: FALSE | AI17: =31 -> 31 | AJ17: =COUNTIF(C17:AG17, TRUE) -> 0 | AK17: =IFERROR(__xludf.DUMMYFUNCTION("SPARKLINE(AJ17/AI17, {""charttype"",""bar"";""max"",1;""color1"",""#90EE90""})"),"")
C18: FALSE | D18: FALSE | E18: FALSE | F18: FALSE | G18: FALSE | H18: FALSE | I18: FALSE | J18: FALSE | K18: FALSE | L18: FALSE | M18: FALSE | N18: FALSE | O18: FALSE | P18: FALSE | Q18: FALSE | R18: FALSE | S18: FALSE | T18: FALSE | U18: FALSE | V18: FALSE | W18: FALSE | X18: FALSE | Y18: FALSE | Z18: FALSE | AA18: FALSE | AB18: FALSE | AC18: FALSE | AD18: FALSE | AE18: FALSE | AF18: FALSE | AG18: FALSE | AI18: =31 -> 31 | AJ18: =COUNTIF(C18:AG18, TRUE) -> 0 | AK18: =IFERROR(__xludf.DUMMYFUNCTION("SPARKLINE(AJ18/AI18, {""charttype"",""bar"";""max"",1;""color1"",""#90EE90""})"),"")
C19: FALSE | D19: FALSE | E19: FALSE | F19: FALSE | G19: FALSE | H19: FALSE | I19: FALSE | J19: FALSE | K19: FALSE | L19: FALSE | M19: FALSE | N19: FALSE | O19: FALSE | P19: FALSE | Q19: FALSE | R19: FALSE | S19: FALSE | T19: FALSE | U19: FALSE | V19: FALSE | W19: FALSE | X19: FALSE | Y19: FALSE | Z19: FALSE | AA19: FALSE | AB19: FALSE | AC19: FALSE | AD19: FALSE | AE19: FALSE | AF19: FALSE | AG19: FALSE | AI19: =31 -> 31 | AJ19: =COUNTIF(C19:AG19, TRUE) -> 0 | AK19: =IFERROR(__xludf.DUMMYFUNCTION("SPARKLINE(AJ19/AI19, {""charttype"",""bar"";""max"",1;""color1"",""#90EE90""})"),"")
B21: Progress | C21: =COUNTIF(C10:C19, TRUE)/COUNTA(C10:C19) -> 0 | D21: =COUNTIF(D10:D19, TRUE)/COUNTA(D10:D19) -> 0 | E21: =COUNTIF(E10:E19, TRUE)/COUNTA(E10:E19) -> 0 | F21: =COUNTIF(F10:F19, TRUE)/COUNTA(F10:F19) -> 0 | G21: =COUNTIF(G10:G19, TRUE)/COUNTA(G10:G19) -> 0 | H21: =COUNTIF(H10:H19, TRUE)/COUNTA(H10:H19) -> 0 | I21: =COUNTIF(I10:I19, TRUE)/COUNTA(I10:I19) -> 0 | J21: =COUNTIF(J10:J19, TRUE)/COUNTA(J10:J19) -> 0 | ... AG21: =COUNTIF(AG10:AG19, TRUE)/COUNTA(AG10:AG19) -> 0
B22: Done | C22: =COUNTIF(C10:C19, TRUE) -> 0 | D22: =COUNTIF(D10:D19, TRUE) -> 0 | E22: =COUNTIF(E10:E19, TRUE) -> 0 | F22: =COUNTIF(F10:F19, TRUE) -> 0 | G22: =COUNTIF(G10:G19, TRUE) -> 0 | H22: =COUNTIF(H10:H19, TRUE) -> 0 | I22: =COUNTIF(I10:I19, TRUE) -> 0 | J22: =COUNTIF(J10:J19, TRUE) -> 0 | ... AG22: =COUNTIF(AG10:AG19, TRUE) -> 0
B23: Not Done | C23: =COUNTIF(C10:C19, FALSE) -> 10 | D23: =COUNTIF(D10:D19, FALSE) -> 10 | E23: =COUNTIF(E10:E19, FALSE) -> 10 | F23: =COUNTIF(F10:F19, FALSE) -> 10 | G23: =COUNTIF(G10:G19, FALSE) -> 10 | H23: =COUNTIF(H10:H19, FALSE) -> 10 | I23: =COUNTIF(I10:I19, FALSE) -> 10 | J23: =COUNTIF(J10:J19, FALSE) -> 10 | ... AG23: =COUNTIF(AG10:AG19, FALSE) -> 10
C33: Mental State
B34: Mood
B35: Motivation
C36: =(C35+C34)/20 -> 0 | D36: =(D35+D34)/20 -> 0 | E36: =(E35+E34)/20 -> 0 | F36: =(F35+F34)/20 -> 0 | G36: =(G35+G34)/20 -> 0 | H36: =(H35+H34)/20 -> 0 | I36: =(I35+I34)/20 -> 0 | J36: =(J35+J34)/20 -> 0 | ... AG36: =(AG35+AG34)/20 -> 0

Sheet Apr
B3: April | J3: Number of habits | P3: Completed habits | V3: Progress | AB3: Progress in %
J4: =COUNTA($B$10:$B$19) -> 0 | P4: =COUNTIF($C$10:$AF$19, TRUE) -> 0 | V4: =IFERROR(__xludf.DUMMYFUNCTION("SPARKLINE(AB4, {""charttype"",""bar"";""max"",1;""color1"",""#90EE90""})"),"") | AB4: =(P4)/(COUNTA($C$10:$C$19)*COUNTA($C$10:$AF$10)) -> 0
B7: My Habits | C7: Week 1 | J7: Week 2 | Q7: Week 3 | X7: Week 4 | AH7: Analysis
C8: We | D8: Th | E8: Fr | F8: Sa | G8: Su | H8: Mo | I8: Tu | J8: We | K8: Th | L8: Fr | M8: Sa | N8: Su | O8: Mo | P8: Tu | Q8: We | R8: Th | S8: Fr | T8: Sa | U8: Su | V8: Mo | W8: Tu | X8: We | Y8: Th | Z8: Fr | AA8: Sa | AB8: Su | AC8: Mo | AD8: Tu | AE8: We | AF8: Th
C9: 1 | D9: 2 | E9: 3 | F9: 4 | G9: 5 | H9: 6 | I9: 7 | J9: 8 | K9: 9 | L9: 10 | M9: 11 | N9: 12 | O9: 13 | P9: 14 | Q9: 15 | R9: 16 | S9: 17 | T9: 18 | U9: 19 | V9: 20 | W9: 21 | X9: 22 | Y9: 23 | Z9: 24 | AA9: 25 | AB9: 26 | AC9: 27 | AD9: 28 | AE9: 29 | AF9: 30 | AH9: Goal | AI9: Actual | AJ9: Progress
C10: FALSE | D10: FALSE | E10: FALSE | F10: FALSE | G10: FALSE | H10: FALSE | I10: FALSE | J10: FALSE | K10: FALSE | L10: FALSE | M10: FALSE | N10: FALSE | O10: FALSE | P10: FALSE | Q10: FALSE | R10: FALSE | S10: FALSE | T10: FALSE | U10: FALSE | V10: FALSE | W10: FALSE | X10: FALSE | Y10: FALSE | Z10: FALSE | AA10: FALSE | AB10: FALSE | AC10: FALSE | AD10: FALSE | AE10: FALSE | AF10: FALSE | AH10: =30 -> 30 | AI10: =COUNTIF(C10:AF10, TRUE) -> 0 | AJ10: =IFERROR(__xludf.DUMMYFUNCTION("SPARKLINE(AI10/AH10, {""charttype"",""bar"";""max"",1;""color1"",""#90EE90""})"),"")
C11: FALSE | D11: FALSE | E11: FALSE | F11: FALSE | G11: FALSE | H11: FALSE | I11: FALSE | J11: FALSE | K11: FALSE | L11: FALSE | M11: FALSE | N11: FALSE | O11: FALSE | P11: FALSE | Q11: FALSE | R11: FALSE | S11: FALSE | T11: FALSE | U11: FALSE | V11: FALSE | W11: FALSE | X11: FALSE | Y11: FALSE | Z11: FALSE | AA11: FALSE | AB11: FALSE | AC11: FALSE | AD11: FALSE | AE11: FALSE | AF11: FALSE | AH11: =30 -> 30 | AI11: =COUNTIF(C11:AF11, TRUE) -> 0 | AJ11: =IFERROR(__xludf.DUMMYFUNCTION("SPARKLINE(AI11/AH11, {""charttype"",""bar"";""max"",1;""color1"",""#90EE90""})"),"")
C12: FALSE | D12: FALSE | E12: FALSE | F12: FALSE | G12: FALSE | H12: FALSE | I12: FALSE | J12: FALSE | K12: FALSE | L12: FALSE | M12: FALSE | N12: FALSE | O12: FALSE | P12: FALSE | Q12: FALSE | R12: FALSE | S12: FALSE | T12: FALSE | U12: FALSE | V12: FALSE | W12: FALSE | X12: FALSE | Y12: FALSE | Z12: FALSE | AA12: FALSE | AB12: FALSE | AC12: FALSE | AD12: FALSE | AE12: FALSE | AF12: FALSE | AH12: =30 -> 30 | AI12: =COUNTIF(C12:AF12, TRUE) -> 0 | AJ12: =IFERROR(__xludf.DUMMYFUNCTION("SPARKLINE(AI12/AH12, {""charttype"",""bar"";""max"",1;""color1"",""#90EE90""})"),"")
C13: FALSE | D13: FALSE | E13: FALSE | F13: FALSE | G13: FALSE | H13: FALSE | I13: FALSE | J13: FALSE | K13: FALSE | L13: FALSE | M13: FALSE | N13: FALSE | O13: FALSE | P13: FALSE | Q13: FALSE | R13: FALSE | S13: FALSE | T13: FALSE | U13: FALSE | V13: FALSE | W13: FALSE | X13: FALSE | Y13: FALSE | Z13: FALSE | AA13: FALSE | AB13: FALSE | AC13: FALSE | AD13: FALSE | AE13: FALSE | AF13: FALSE | AH13: =30 -> 30 | AI13: =COUNTIF(C13:AF13, TRUE) -> 0 | AJ13: =IFERROR(__xludf.DUMMYFUNCTION("SPARKLINE(AI13/AH13, {""charttype"",""bar"";""max"",1;""color1"",""#90EE90""})"),"")
C14: FALSE | D14: FALSE | E14: FALSE | F14: FALSE | G14: FALSE | H14: FALSE | I14: FALSE | J14: FALSE | K14: FALSE | L14: FALSE | M14: FALSE | N14: FALSE | O14: FALSE | P14: FALSE | Q14: FALSE | R14: FALSE | S14: FALSE | T14: FALSE | U14: FALSE | V14: FALSE | W14: FALSE | X14: FALSE | Y14: FALSE | Z14: FALSE | AA14: FALSE | AB14: FALSE | AC14: FALSE | AD14: FALSE | AE14: FALSE | AF14: FALSE | AH14: =30 -> 30 | AI14: =COUNTIF(C14:AF14, TRUE) -> 0 | AJ14: =IFERROR(__xludf.DUMMYFUNCTION("SPARKLINE(AI14/AH14, {""charttype"",""bar"";""max"",1;""color1"",""#90EE90""})"),"")
C15: FALSE | D15: FALSE | E15: FALSE | F15: FALSE | G15: FALSE | H15: FALSE | I15: FALSE | J15: FALSE | K15: FALSE | L15: FALSE | M15: FALSE | N15: FALSE | O15: FALSE | P15: FALSE | Q15: FALSE | R15: FALSE | S15: FALSE | T15: FALSE | U15: FALSE | V15: FALSE | W15: FALSE | X15: FALSE | Y15: FALSE | Z15: FALSE | AA15: FALSE | AB15: FALSE | AC15: FALSE | AD15: FALSE | AE15: FALSE | AF15: FALSE | AH15: =30 -> 30 | AI15: =COUNTIF(C15:AF15, TRUE) -> 0 | AJ15: =IFERROR(__xludf.DUMMYFUNCTION("SPARKLINE(AI15/AH15, {""charttype"",""bar"";""max"",1;""color1"",""#90EE90""})"),"")
C16: FALSE | D16: FALSE | E16: FALSE | F16: FALSE | G16: FALSE | H16: FALSE | I16: FALSE | J16: FALSE | K16: FALSE | L16: FALSE | M16: FALSE | N16: FALSE | O16: FALSE | P16: FALSE | Q16: FALSE | R16: FALSE | S16: FALSE | T16: FALSE | U16: FALSE | V16: FALSE | W16: FALSE | X16: FALSE | Y16: FALSE | Z16: FALSE | AA16: FALSE | AB16: FALSE | AC16: FALSE | AD16: FALSE | AE16: FALSE | AF16: FALSE | AH16: =30 -> 30 | AI16: =COUNTIF(C16:AF16, TRUE) -> 0 | AJ16: =IFERROR(__xludf.DUMMYFUNCTION("SPARKLINE(AI16/AH16, {""charttype"",""bar"";""max"",1;""color1"",""#90EE90""})"),"")
C17: FALSE | D17: FALSE | E17: FALSE | F17: FALSE | G17: FALSE | H17: FALSE | I17: FALSE | J17: FALSE | K17: FALSE | L17: FALSE | M17: FALSE | N17: FALSE | O17: FALSE | P17: FALSE | Q17: FALSE | R17: FALSE | S17: FALSE | T17: FALSE | U17: FALSE | V17: FALSE | W17: FALSE | X17: FALSE | Y17: FALSE | Z17: FALSE | AA17: FALSE | AB17: FALSE | AC17: FALSE | AD17: FALSE | AE17: FALSE | AF17: FALSE | AH17: =30 -> 30 | AI17: =COUNTIF(C17:AF17, TRUE) -> 0 | AJ17: =IFERROR(__xludf.DUMMYFUNCTION("SPARKLINE(AI17/AH17, {""charttype"",""bar"";""max"",1;""color1"",""#90EE90""})"),"")
C18: FALSE | D18: FALSE | E18: FALSE | F18: FALSE | G18: FALSE | H18: FALSE | I18: FALSE | J18: FALSE | K18: FALSE | L18: FALSE | M18: FALSE | N18: FALSE | O18: FALSE | P18: FALSE | Q18: FALSE | R18: FALSE | S18: FALSE | T18: FALSE | U18: FALSE | V18: FALSE | W18: FALSE | X18: FALSE | Y18: FALSE | Z18: FALSE | AA18: FALSE | AB18: FALSE | AC18: FALSE | AD18: FALSE | AE18: FALSE | AF18: FALSE | AH18: =30 -> 30 | AI18: =COUNTIF(C18:AF18, TRUE) -> 0 | AJ18: =IFERROR(__xludf.DUMMYFUNCTION("SPARKLINE(AI18/AH18, {""charttype"",""bar"";""max"",1;""color1"",""#90EE90""})"),"")
C19: FALSE | D19: FALSE | E19: FALSE | F19: FALSE | G19: FALSE | H19: FALSE | I19: FALSE | J19: FALSE | K19: FALSE | L19: FALSE | M19: FALSE | N19: FALSE | O19: FALSE | P19: FALSE | Q19: FALSE | R19: FALSE | S19: FALSE | T19: FALSE | U19: FALSE | V19: FALSE | W19: FALSE | X19: FALSE | Y19: FALSE | Z19: FALSE | AA19: FALSE | AB19: FALSE | AC19: FALSE | AD19: FALSE | AE19: FALSE | AF19: FALSE | AH19: =30 -> 30 | AI19: =COUNTIF(C19:AF19, TRUE) -> 0 | AJ19: =IFERROR(__xludf.DUMMYFUNCTION("SPARKLINE(AI19/AH19, {""charttype"",""bar"";""max"",1;""color1"",""#90EE90""})"),"")
B21: Progress | C21: =COUNTIF(C10:C19, TRUE)/COUNTA(C10:C19) -> 0 | D21: =COUNTIF(D10:D19, TRUE)/COUNTA(D10:D19) -> 0 | E21: =COUNTIF(E10:E19, TRUE)/COUNTA(E10:E19) -> 0 | F21: =COUNTIF(F10:F19, TRUE)/COUNTA(F10:F19) -> 0 | G21: =COUNTIF(G10:G19, TRUE)/COUNTA(G10:G19) -> 0 | H21: =COUNTIF(H10:H19, TRUE)/COUNTA(H10:H19) -> 0 | I21: =COUNTIF(I10:I19, TRUE)/COUNTA(I10:I19) -> 0 | J21: =COUNTIF(J10:J19, TRUE)/COUNTA(J10:J19) -> 0 | ... AF21: =COUNTIF(AF10:AF19, TRUE)/COUNTA(AF10:AF19) -> 0
B22: Done | C22: =COUNTIF(C10:C19, TRUE) -> 0 | D22: =COUNTIF(D10:D19, TRUE) -> 0 | E22: =COUNTIF(E10:E19, TRUE) -> 0 | F22: =COUNTIF(F10:F19, TRUE) -> 0 | G22: =COUNTIF(G10:G19, TRUE) -> 0 | H22: =COUNTIF(H10:H19, TRUE) -> 0 | I22: =COUNTIF(I10:I19, TRUE) -> 0 | J22: =COUNTIF(J10:J19, TRUE) -> 0 | ... AF22: =COUNTIF(AF10:AF19, TRUE) -> 0
B23: Not Done | C23: =COUNTIF(C10:C19, FALSE) -> 10 | D23: =COUNTIF(D10:D19, FALSE) -> 10 | E23: =COUNTIF(E10:E19, FALSE) -> 10 | F23: =COUNTIF(F10:F19, FALSE) -> 10 | G23: =COUNTIF(G10:G19, FALSE) -> 10 | H23: =COUNTIF(H10:H19, FALSE) -> 10 | I23: =COUNTIF(I10:I19, FALSE) -> 10 | J23: =COUNTIF(J10:J19, FALSE) -> 10 | ... AF23: =COUNTIF(AF10:AF19, FALSE) -> 10
C33: Mental State
B34: Mood
B35: Motivation
C36: =(C35+C34)/20 -> 0 | D36: =(D35+D34)/20 -> 0 | E36: =(E35+E34)/20 -> 0 | F36: =(F35+F34)/20 -> 0 | G36: =(G35+G34)/20 -> 0 | H36: =(H35+H34)/20 -> 0 | I36: =(I35+I34)/20 -> 0 | J36: =(J35+J34)/20 -> 0 | ... AF36: =(AF35+AF34)/20 -> 0

Sheet May
B3: May | J3: Number of habits | P3: Completed habits | V3: Progress | AB3: Progress in %
J4: =COUNTA($B$10:$B$19) -> 0 | P4: =COUNTIF($C$10:$AF$19, TRUE) -> 0 | V4: =IFERROR(__xludf.DUMMYFUNCTION("SPARKLINE(AB4, {""charttype"",""bar"";""max"",1;""color1"",""#90EE90""})"),"") | AB4: =(P4)/(COUNTA($C$10:$C$19)*COUNTA($C$10:$AG$10)) -> 0
B7: My Habits | C7: Week 1 | J7: Week 2 | Q7: Week 3 | X7: Week 4 | AI7: Analysis
C8: Fr | D8: Sa | E8: Su | F8: Mo | G8: Tu | H8: We | I8: Th | J8: Fr | K8: Sa | L8: Su | M8: Mo | N8: Tu | O8: We | P8: Th | Q8: Fr | R8: Sa | S8: Su | T8: Mo | U8: Tu | V8: We | W8: Th | X8: Fr | Y8: Sa | Z8: Su | AA8: Mo | AB8: Tu | AC8: We | AD8: Th | AE8: Fr | AF8: Sa | AG8: Su
C9: 1 | D9: 2 | E9: 3 | F9: 4 | G9: 5 | H9: 6 | I9: 7 | J9: 8 | K9: 9 | L9: 10 | M9: 11 | N9: 12 | O9: 13 | P9: 14 | Q9: 15 | R9: 16 | S9: 17 | T9: 18 | U9: 19 | V9: 20 | W9: 21 | X9: 22 | Y9: 23 | Z9: 24 | AA9: 25 | AB9: 26 | AC9: 27 | AD9: 28 | AE9: 29 | AF9: 30 | AG9: 31 | AI9: Goal | AJ9: Actual | AK9: Progress
C10: FALSE | D10: FALSE | E10: FALSE | F10: FALSE | G10: FALSE | H10: FALSE | I10: FALSE | J10: FALSE | K10: FALSE | L10: FALSE | M10: FALSE | N10: FALSE | O10: FALSE | P10: FALSE | Q10: FALSE | R10: FALSE | S10: FALSE | T10: FALSE | U10: FALSE | V10: FALSE | W10: FALSE | X10: FALSE | Y10: FALSE | Z10: FALSE | AA10: FALSE | AB10: FALSE | AC10: FALSE | AD10: FALSE | AE10: FALSE | AF10: FALSE | AG10: FALSE | AI10: =31 -> 31 | AJ10: =COUNTIF(C10:AG10, TRUE) -> 0 | AK10: =IFERROR(__xludf.DUMMYFUNCTION("SPARKLINE(AJ10/AI10, {""charttype"",""bar"";""max"",1;""color1"",""#90EE90""})"),"")
C11: FALSE | D11: FALSE | E11: FALSE | F11: FALSE | G11: FALSE | H11: FALSE | I11: FALSE | J11: FALSE | K11: FALSE | L11: FALSE | M11: FALSE | N11: FALSE | O11: FALSE | P11: FALSE | Q11: FALSE | R11: FALSE | S11: FALSE | T11: FALSE | U11: FALSE | V11: FALSE | W11: FALSE | X11: FALSE | Y11: FALSE | Z11: FALSE | AA11: FALSE | AB11: FALSE | AC11: FALSE | AD11: FALSE | AE11: FALSE | AF11: FALSE | AG11: FALSE | AI11: =31 -> 31 | AJ11: =COUNTIF(C11:AG11, TRUE) -> 0 | AK11: =IFERROR(__xludf.DUMMYFUNCTION("SPARKLINE(AJ11/AI11, {""charttype"",""bar"";""max"",1;""color1"",""#90EE90""})"),"")
C12: FALSE | D12: FALSE | E12: FALSE | F12: FALSE | G12: FALSE | H12: FALSE | I12: FALSE | J12: FALSE | K12: FALSE | L12: FALSE | M12: FALSE | N12: FALSE | O12: FALSE | P12: FALSE | Q12: FALSE | R12: FALSE | S12: FALSE | T12: FALSE | U12: FALSE | V12: FALSE | W12: FALSE | X12: FALSE | Y12: FALSE | Z12: FALSE | AA12: FALSE | AB12: FALSE | AC12: FALSE | AD12: FALSE | AE12: FALSE | AF12: FALSE | AG12: FALSE | AI12: =31 -> 31 | AJ12: =COUNTIF(C12:AG12, TRUE) -> 0 | AK12: =IFERROR(__xludf.DUMMYFUNCTION("SPARKLINE(AJ12/AI12, {""charttype"",""bar"";""max"",1;""color1"",""#90EE90""})"),"")
C13: FALSE | D13: FALSE | E13: FALSE | F13: FALSE | G13: FALSE | H13: FALSE | I13: FALSE | J13: FALSE | K13: FALSE | L13: FALSE | M13: FALSE | N13: FALSE | O13: FALSE | P13: FALSE | Q13: FALSE | R13: FALSE | S13: FALSE | T13: FALSE | U13: FALSE | V13: FALSE | W13: FALSE | X13: FALSE | Y13: FALSE | Z13: FALSE | AA13: FALSE | AB13: FALSE | AC13: FALSE | AD13: FALSE | AE13: FALSE | AF13: FALSE | AG13: FALSE | AI13: =31 -> 31 | AJ13: =COUNTIF(C13:AG13, TRUE) -> 0 | AK13: =IFERROR(__xludf.DUMMYFUNCTION("SPARKLINE(AJ13/AI13, {""charttype"",""bar"";""max"",1;""color1"",""#90EE90""})"),"")
C14: FALSE | D14: FALSE | E14: FALSE | F14: FALSE | G14: FALSE | H14: FALSE | I14: FALSE | J14: FALSE | K14: FALSE | L14: FALSE | M14: FALSE | N14: FALSE | O14: FALSE | P14: FALSE | Q14: FALSE | R14: FALSE | S14: FALSE | T14: FALSE | U14: FALSE | V14: FALSE | W14: FALSE | X14: FALSE | Y14: FALSE | Z14: FALSE | AA14: FALSE | AB14: FALSE | AC14: FALSE | AD14: FALSE | AE14: FALSE | AF14: FALSE | AG14: FALSE | AI14: =31 -> 31 | AJ14: =COUNTIF(C14:AG14, TRUE) -> 0 | AK14: =IFERROR(__xludf.DUMMYFUNCTION("SPARKLINE(AJ14/AI14, {""charttype"",""bar"";""max"",1;""color1"",""#90EE90""})"),"")
C15: FALSE | D15: FALSE | E15: FALSE | F15: FALSE | G15: FALSE | H15: FALSE | I15: FALSE | J15: FALSE | K15: FALSE | L15: FALSE | M15: FALSE | N15: FALSE | O15: FALSE | P15: FALSE | Q15: FALSE | R15: FALSE | S15: FALSE | T15: FALSE | U15: FALSE | V15: FALSE | W15: FALSE | X15: FALSE | Y15: FALSE | Z15: FALSE | AA15: FALSE | AB15: FALSE | AC15: FALSE | AD15: FALSE | AE15: FALSE | AF15: FALSE | AG15: FALSE | AI15: =31 -> 31 | AJ15: =COUNTIF(C15:AG15, TRUE) -> 0 | AK15: =IFERROR(__xludf.DUMMYFUNCTION("SPARKLINE(AJ15/AI15, {""charttype"",""bar"";""max"",1;""color1"",""#90EE90""})"),"")
C16: FALSE | D16: FALSE | E16: FALSE | F16: FALSE | G16: FALSE | H16: FALSE | I16: FALSE | J16: FALSE | K16: FALSE | L16: FALSE | M16: FALSE | N16: FALSE | O16: FALSE | P16: FALSE | Q16: FALSE | R16: FALSE | S16: FALSE | T16: FALSE | U16: FALSE | V16: FALSE | W16: FALSE | X16: FALSE | Y16: FALSE | Z16: FALSE | AA16: FALSE | AB16: FALSE | AC16: FALSE | AD16: FALSE | AE16: FALSE | AF16: FALSE | AG16: FALSE | AI16: =31 -> 31 | AJ16: =COUNTIF(C16:AG16, TRUE) -> 0 | AK16: =IFERROR(__xludf.DUMMYFUNCTION("SPARKLINE(AJ16/AI16, {""charttype"",""bar"";""max"",1;""color1"",""#90EE90""})"),"")
C17: FALSE | D17: FALSE | E17: FALSE | F17: FALSE | G17: FALSE | H17: FALSE | I17: FALSE | J17: FALSE | K17: FALSE | L17: FALSE | M17: FALSE | N17: FALSE | O17: FALSE | P17: FALSE | Q17: FALSE | R17: FALSE | S17: FALSE | T17: FALSE | U17: FALSE | V17: FALSE | W17: FALSE | X17: FALSE | Y17: FALSE | Z17: FALSE | AA17: FALSE | AB17: FALSE | AC17: FALSE | AD17: FALSE | AE17: FALSE | AF17: FALSE | AG17: FALSE | AI17: =31 -> 31 | AJ17: =COUNTIF(C17:AG17, TRUE) -> 0 | AK17: =IFERROR(__xludf.DUMMYFUNCTION("SPARKLINE(AJ17/AI17, {""charttype"",""bar"";""max"",1;""color1"",""#90EE90""})"),"")
C18: FALSE | D18: FALSE | E18: FALSE | F18: FALSE | G18: FALSE | H18: FALSE | I18: FALSE | J18: FALSE | K18: FALSE | L18: FALSE | M18: FALSE | N18: FALSE | O18: FALSE | P18: FALSE | Q18: FALSE | R18: FALSE | S18: FALSE | T18: FALSE | U18: FALSE | V18: FALSE | W18: FALSE | X18: FALSE | Y18: FALSE | Z18: FALSE | AA18: FALSE | AB18: FALSE | AC18: FALSE | AD18: FALSE | AE18: FALSE | AF18: FALSE | AG18: FALSE | AI18: =31 -> 31 | AJ18: =COUNTIF(C18:AG18, TRUE) -> 0 | AK18: =IFERROR(__xludf.DUMMYFUNCTION("SPARKLINE(AJ18/AI18, {""charttype"",""bar"";""max"",1;""color1"",""#90EE90""})"),"")
C19: FALSE | D19: FALSE | E19: FALSE | F19: FALSE | G19: FALSE | H19: FALSE | I19: FALSE | J19: FALSE | K19: FALSE | L19: FALSE | M19: FALSE | N19: FALSE | O19: FALSE | P19: FALSE | Q19: FALSE | R19: FALSE | S19: FALSE | T19: FALSE | U19: FALSE | V19: FALSE | W19: FALSE | X19: FALSE | Y19: FALSE | Z19: FALSE | AA19: FALSE | AB19: FALSE | AC19: FALSE | AD19: FALSE | AE19: FALSE | AF19: FALSE | AG19: FALSE | AI19: =31 -> 31 | AJ19: =COUNTIF(C19:AG19, TRUE) -> 0 | AK19: =IFERROR(__xludf.DUMMYFUNCTION("SPARKLINE(AJ19/AI19, {""charttype"",""bar"";""max"",1;""color1"",""#90EE90""})"),"")
B21: Progress | C21: =COUNTIF(C10:C19, TRUE)/COUNTA(C10:C19) -> 0 | D21: =COUNTIF(D10:D19, TRUE)/COUNTA(D10:D19) -> 0 | E21: =COUNTIF(E10:E19, TRUE)/COUNTA(E10:E19) -> 0 | F21: =COUNTIF(F10:F19, TRUE)/COUNTA(F10:F19) -> 0 | G21: =COUNTIF(G10:G19, TRUE)/COUNTA(G10:G19) -> 0 | H21: =COUNTIF(H10:H19, TRUE)/COUNTA(H10:H19) -> 0 | I21: =COUNTIF(I10:I19, TRUE)/COUNTA(I10:I19) -> 0 | J21: =COUNTIF(J10:J19, TRUE)/COUNTA(J10:J19) -> 0 | ... AG21: =COUNTIF(AG10:AG19, TRUE)/COUNTA(AG10:AG19) -> 0
B22: Done | C22: =COUNTIF(C10:C19, TRUE) -> 0 | D22: =COUNTIF(D10:D19, TRUE) -> 0 | E22: =COUNTIF(E10:E19, TRUE) -> 0 | F22: =COUNTIF(F10:F19, TRUE) -> 0 | G22: =COUNTIF(G10:G19, TRUE) -> 0 | H22: =COUNTIF(H10:H19, TRUE) -> 0 | I22: =COUNTIF(I10:I19, TRUE) -> 0 | J22: =COUNTIF(J10:J19, TRUE) -> 0 | ... AG22: =COUNTIF(AG10:AG19, TRUE) -> 0
B23: Not Done | C23: =COUNTIF(C10:C19, FALSE) -> 10 | D23: =COUNTIF(D10:D19, FALSE) -> 10 | E23: =COUNTIF(E10:E19, FALSE) -> 10 | F23: =COUNTIF(F10:F19, FALSE) -> 10 | G23: =COUNTIF(G10:G19, FALSE) -> 10 | H23: =COUNTIF(H10:H19, FALSE) -> 10 | I23: =COUNTIF(I10:I19, FALSE) -> 10 | J23: =COUNTIF(J10:J19, FALSE) -> 10 | ... AG23: =COUNTIF(AG10:AG19, FALSE) -> 10
C33: Mental State
B34: Mood
B35: Motivation
C36: =(C35+C34)/20 -> 0 | D36: =(D35+D34)/20 -> 0 | E36: =(E35+E34)/20 -> 0 | F36: =(F35+F34)/20 -> 0 | G36: =(G35+G34)/20 -> 0 | H36: =(H35+H34)/20 -> 0 | I36: =(I35+I34)/20 -> 0 | J36: =(J35+J34)/20 -> 0 | ... AG36: =(AG35+AG34)/20 -> 0

Sheet Jun
B3: June | J3: Number of habits | P3: Completed habits | V3: Progress | AB3: Progress in %
J4: =COUNTA($B$10:$B$19) -> 0 | P4: =COUNTIF($C$10:$AF$19, TRUE) -> 0 | V4: =IFERROR(__xludf.DUMMYFUNCTION("SPARKLINE(AB4, {""charttype"",""bar"";""max"",1;""color1"",""#90EE90""})"),"") | AB4: =(P4)/(COUNTA($C$10:$C$19)*COUNTA($C$10:$AF$10)) -> 0
B7: My Habits | C7: Week 1 | J7: Week 2 | Q7: Week 3 | X7: Week 4 | AH7: Analysis
C8: Mo | D8: Tu | E8: We | F8: Th | G8: Fr | H8: Sa | I8: Su | J8: Mo | K8: Tu | L8: We | M8: Th | N8: Fr | O8: Sa | P8: Su | Q8: Mo | R8: Tu | S8: We | T8: Th | U8: Fr | V8: Sa | W8: Su | X8: Mo | Y8: Tu | Z8: We | AA8: Th | AB8: Fr | AC8: Sa | AD8: Su | AE8: Mo | AF8: Tu
C9: 1 | D9: 2 | E9: 3 | F9: 4 | G9: 5 | H9: 6 | I9: 7 | J9: 8 | K9: 9 | L9: 10 | M9: 11 | N9: 12 | O9: 13 | P9: 14 | Q9: 15 | R9: 16 | S9: 17 | T9: 18 | U9: 19 | V9: 20 | W9: 21 | X9: 22 | Y9: 23 | Z9: 24 | AA9: 25 | AB9: 26 | AC9: 27 | AD9: 28 | AE9: 29 | AF9: 30 | AH9: Goal | AI9: Actual | AJ9: Progress
C10: FALSE | D10: FALSE | E10: FALSE | F10: FALSE | G10: FALSE | H10: FALSE | I10: FALSE | J10: FALSE | K10: FALSE | L10: FALSE | M10: FALSE | N10: FALSE | O10: FALSE | P10: FALSE | Q10: FALSE | R10: FALSE | S10: FALSE | T10: FALSE | U10: FALSE | V10: FALSE | W10: FALSE | X10: FALSE | Y10: FALSE | Z10: FALSE | AA10: FALSE | AB10: FALSE | AC10: FALSE | AD10: FALSE | AE10: FALSE | AF10: FALSE | AH10: =30 -> 30 | AI10: =COUNTIF(C10:AF10, TRUE) -> 0 | AJ10: =IFERROR(__xludf.DUMMYFUNCTION("SPARKLINE(AI10/AH10, {""charttype"",""bar"";""max"",1;""color1"",""#90EE90""})"),"")
C11: FALSE | D11: FALSE | E11: FALSE | F11: FALSE | G11: FALSE | H11: FALSE | I11: FALSE | J11: FALSE | K11: FALSE | L11: FALSE | M11: FALSE | N11: FALSE | O11: FALSE | P11: FALSE | Q11: FALSE | R11: FALSE | S11: FALSE | T11: FALSE | U11: FALSE | V11: FALSE | W11: FALSE | X11: FALSE | Y11: FALSE | Z11: FALSE | AA11: FALSE | AB11: FALSE | AC11: FALSE | AD11: FALSE | AE11: FALSE | AF11: FALSE | AH11: =30 -> 30 | AI11: =COUNTIF(C11:AF11, TRUE) -> 0 | AJ11: =IFERROR(__xludf.DUMMYFUNCTION("SPARKLINE(AI11/AH11, {""charttype"",""bar"";""max"",1;""color1"",""#90EE90""})"),"")
C12: FALSE | D12: FALSE | E12: FALSE | F12: FALSE | G12: FALSE | H12: FALSE | I12: FALSE | J12: FALSE | K12: FALSE | L12: FALSE | M12: FALSE | N12: FALSE | O12: FALSE | P12: FALSE | Q12: FALSE | R12: FALSE | S12: FALSE | T12: FALSE | U12: FALSE | V12: FALSE | W12: FALSE | X12: FALSE | Y12: FALSE | Z12: FALSE | AA12: FALSE | AB12: FALSE | AC12: FALSE | AD12: FALSE | AE12: FALSE | AF12: FALSE | AH12: =30 -> 30 | AI12: =COUNTIF(C12:AF12, TRUE) -> 0 | AJ12: =IFERROR(__xludf.DUMMYFUNCTION("SPARKLINE(AI12/AH12, {""charttype"",""bar"";""max"",1;""color1"",""#90EE90""})"),"")
C13: FALSE | D13: FALSE | E13: FALSE | F13: FALSE | G13: FALSE | H13: FALSE | I13: FALSE | J13: FALSE | K13: FALSE | L13: FALSE | M13: FALSE | N13: FALSE | O13: FALSE | P13: FALSE | Q13: FALSE | R13: FALSE | S13: FALSE | T13: FALSE | U13: FALSE | V13: FALSE | W13: FALSE | X13: FALSE | Y13: FALSE | Z13: FALSE | AA13: FALSE | AB13: FALSE | AC13: FALSE | AD13: FALSE | AE13: FALSE | AF13: FALSE | AH13: =30 -> 30 | AI13: =COUNTIF(C13:AF13, TRUE) -> 0 | AJ13: =IFERROR(__xludf.DUMMYFUNCTION("SPARKLINE(AI13/AH13, {""charttype"",""bar"";""max"",1;""color1"",""#90EE90""})"),"")
C14: FALSE | D14: FALSE | E14: FALSE | F14: FALSE | G14: FALSE | H14: FALSE | I14: FALSE | J14: FALSE | K14: FALSE | L14: FALSE | M14: FALSE | N14: FALSE | O14: FALSE | P14: FALSE | Q14: FALSE | R14: FALSE | S14: FALSE | T14: FALSE | U14: FALSE | V14: FALSE | W14: FALSE | X14: FALSE | Y14: FALSE | Z14: FALSE | AA14: FALSE | AB14: FALSE | AC14: FALSE | AD14: FALSE | AE14: FALSE | AF14: FALSE | AH14: =30 -> 30 | AI14: =COUNTIF(C14:AF14, TRUE) -> 0 | AJ14: =IFERROR(__xludf.DUMMYFUNCTION("SPARKLINE(AI14/AH14, {""charttype"",""bar"";""max"",1;""color1"",""#90EE90""})"),"")
C15: FALSE | D15: FALSE | E15: FALSE | F15: FALSE | G15: FALSE | H15: FALSE | I15: FALSE | J15: FALSE | K15: FALSE | L15: FALSE | M15: FALSE | N15: FALSE | O15: FALSE | P15: FALSE | Q15: FALSE | R15: FALSE | S15: FALSE | T15: FALSE | U15: FALSE | V15: FALSE | W15: FALSE | X15: FALSE | Y15: FALSE | Z15: FALSE | AA15: FALSE | AB15: FALSE | AC15: FALSE | AD15: FALSE | AE15: FALSE | AF15: FALSE | AH15: =30 -> 30 | AI15: =COUNTIF(C15:AF15, TRUE) -> 0 | AJ15: =IFERROR(__xludf.DUMMYFUNCTION("SPARKLINE(AI15/AH15, {""charttype"",""bar"";""max"",1;""color1"",""#90EE90""})"),"")
C16: FALSE | D16: FALSE | E16: FALSE | F16: FALSE | G16: FALSE | H16: FALSE | I16: FALSE | J16: FALSE | K16: FALSE | L16: FALSE | M16: FALSE | N16: FALSE | O16: FALSE | P16: FALSE | Q16: FALSE | R16: FALSE | S16: FALSE | T16: FALSE | U16: FALSE | V16: FALSE | W16: FALSE | X16: FALSE | Y16: FALSE | Z16: FALSE | AA16: FALSE | AB16: FALSE | AC16: FALSE | AD16: FALSE | AE16: FALSE | AF16: FALSE | AH16: =30 -> 30 | AI16: =COUNTIF(C16:AF16, TRUE) -> 0 | AJ16: =IFERROR(__xludf.DUMMYFUNCTION("SPARKLINE(AI16/AH16, {""charttype"",""bar"";""max"",1;""color1"",""#90EE90""})"),"")
C17: FALSE | D17: FALSE | E17: FALSE | F17: FALSE | G17: FALSE | H17: FALSE | I17: FALSE | J17: FALSE | K17: FALSE | L17: FALSE | M17: FALSE | N17: FALSE | O17: FALSE | P17: FALSE | Q17: FALSE | R17: FALSE | S17: FALSE | T17: FALSE | U17: FALSE | V17: FALSE | W17: FALSE | X17: FALSE | Y17: FALSE | Z17: FALSE | AA17: FALSE | AB17: FALSE | AC17: FALSE | AD17: FALSE | AE17: FALSE | AF17: FALSE | AH17: =30 -> 30 | AI17: =COUNTIF(C17:AF17, TRUE) -> 0 | AJ17: =IFERROR(__xludf.DUMMYFUNCTION("SPARKLINE(AI17/AH17, {""charttype"",""bar"";""max"",1;""color1"",""#90EE90""})"),"")
C18: FALSE | D18: FALSE | E18: FALSE | F18: FALSE | G18: FALSE | H18: FALSE | I18: FALSE | J18: FALSE | K18: FALSE | L18: FALSE | M18: FALSE | N18: FALSE | O18: FALSE | P18: FALSE | Q18: FALSE | R18: FALSE | S18: FALSE | T18: FALSE | U18: FALSE | V18: FALSE | W18: FALSE | X18: FALSE | Y18: FALSE | Z18: FALSE | AA18: FALSE | AB18: FALSE | AC18: FALSE | AD18: FALSE | AE18: FALSE | AF18: FALSE | AH18: =30 -> 30 | AI18: =COUNTIF(C18:AF18, TRUE) -> 0 | AJ18: =IFERROR(__xludf.DUMMYFUNCTION("SPARKLINE(AI18/AH18, {""charttype"",""bar"";""max"",1;""color1"",""#90EE90""})"),"")
C19: FALSE | D19: FALSE | E19: FALSE | F19: FALSE | G19: FALSE | H19: FALSE | I19: FALSE | J19: FALSE | K19: FALSE | L19: FALSE | M19: FALSE | N19: FALSE | O19: FALSE | P19: FALSE | Q19: FALSE | R19: FALSE | S19: FALSE | T19: FALSE | U19: FALSE | V19: FALSE | W19: FALSE | X19: FALSE | Y19: FALSE | Z19: FALSE | AA19: FALSE | AB19: FALSE | AC19: FALSE | AD19: FALSE | AE19: FALSE | AF19: FALSE | AH19: =30 -> 30 | AI19: =COUNTIF(C19:AF19, TRUE) -> 0 | AJ19: =IFERROR(__xludf.DUMMYFUNCTION("SPARKLINE(AI19/AH19, {""charttype"",""bar"";""max"",1;""color1"",""#90EE90""})"),"")
B21: Progress | C21: =COUNTIF(C10:C19, TRUE)/COUNTA(C10:C19) -> 0 | D21: =COUNTIF(D10:D19, TRUE)/COUNTA(D10:D19) -> 0 | E21: =COUNTIF(E10:E19, TRUE)/COUNTA(E10:E19) -> 0 | F21: =COUNTIF(F10:F19, TRUE)/COUNTA(F10:F19) -> 0 | G21: =COUNTIF(G10:G19, TRUE)/COUNTA(G10:G19) -> 0 | H21: =COUNTIF(H10:H19, TRUE)/COUNTA(H10:H19) -> 0 | I21: =COUNTIF(I10:I19, TRUE)/COUNTA(I10:I19) -> 0 | J21: =COUNTIF(J10:J19, TRUE)/COUNTA(J10:J19) -> 0 | ... AF21: =COUNTIF(AF10:AF19, TRUE)/COUNTA(AF10:AF19) -> 0
